[2022-12-01T16:28:58.378+0000] {taskinstance.py:1165} INFO - Dependencies all met for <TaskInstance: first_dag.pull_task manual__2022-12-01T16:28:53.311369+00:00 [queued]>
[2022-12-01T16:28:58.389+0000] {taskinstance.py:1165} INFO - Dependencies all met for <TaskInstance: first_dag.pull_task manual__2022-12-01T16:28:53.311369+00:00 [queued]>
[2022-12-01T16:28:58.390+0000] {taskinstance.py:1362} INFO - 
--------------------------------------------------------------------------------
[2022-12-01T16:28:58.390+0000] {taskinstance.py:1363} INFO - Starting attempt 1 of 1
[2022-12-01T16:28:58.390+0000] {taskinstance.py:1364} INFO - 
--------------------------------------------------------------------------------
[2022-12-01T16:28:58.407+0000] {taskinstance.py:1383} INFO - Executing <Task(PythonOperator): pull_task> on 2022-12-01 16:28:53.311369+00:00
[2022-12-01T16:28:58.413+0000] {standard_task_runner.py:55} INFO - Started process 950 to run task
[2022-12-01T16:28:58.417+0000] {standard_task_runner.py:82} INFO - Running: ['***', 'tasks', 'run', 'first_dag', 'pull_task', 'manual__2022-12-01T16:28:53.311369+00:00', '--job-id', '849', '--raw', '--subdir', 'DAGS_FOLDER/***1t.py', '--cfg-path', '/tmp/tmpvxcd5xqt']
[2022-12-01T16:28:58.419+0000] {standard_task_runner.py:83} INFO - Job 849: Subtask pull_task
[2022-12-01T16:28:58.487+0000] {task_command.py:376} INFO - Running <TaskInstance: first_dag.pull_task manual__2022-12-01T16:28:53.311369+00:00 [running]> on host debdf09646d4
[2022-12-01T16:28:58.556+0000] {taskinstance.py:1592} INFO - Exporting the following env vars:
AIRFLOW_CTX_DAG_OWNER=***
AIRFLOW_CTX_DAG_ID=first_dag
AIRFLOW_CTX_TASK_ID=pull_task
AIRFLOW_CTX_EXECUTION_DATE=2022-12-01T16:28:53.311369+00:00
AIRFLOW_CTX_TRY_NUMBER=1
AIRFLOW_CTX_DAG_RUN_ID=manual__2022-12-01T16:28:53.311369+00:00
[2022-12-01T16:28:58.558+0000] {taskinstance.py:1851} ERROR - Task failed with exception
Traceback (most recent call last):
  File "/home/airflow/.local/lib/python3.7/site-packages/airflow/operators/python.py", line 175, in execute
    return_value = self.execute_callable()
  File "/home/airflow/.local/lib/python3.7/site-packages/airflow/operators/python.py", line 193, in execute_callable
    return self.python_callable(*self.op_args, **self.op_kwargs)
  File "/opt/airflow/dags/airflow1t.py", line 31, in pull_function
    ls = ti.xcom_push(task_ids='len_csv')
  File "/home/airflow/.local/lib/python3.7/site-packages/airflow/utils/session.py", line 75, in wrapper
    return func(*args, session=session, **kwargs)
TypeError: xcom_push() got an unexpected keyword argument 'task_ids'
[2022-12-01T16:28:58.568+0000] {taskinstance.py:1406} INFO - Marking task as FAILED. dag_id=first_dag, task_id=pull_task, execution_date=20221201T162853, start_date=20221201T162858, end_date=20221201T162858
[2022-12-01T16:28:58.582+0000] {standard_task_runner.py:105} ERROR - Failed to execute job 849 for task pull_task (xcom_push() got an unexpected keyword argument 'task_ids'; 950)
[2022-12-01T16:28:58.628+0000] {local_task_job.py:159} INFO - Task exited with return code 1
[2022-12-01T16:28:58.647+0000] {taskinstance.py:2623} INFO - 0 downstream tasks scheduled from follow-on schedule check
