[2022-11-30T19:03:52.640+0000] {taskinstance.py:1165} INFO - Dependencies all met for <TaskInstance: first_dag.ford_dataset manual__2022-11-30T19:03:48.187324+00:00 [queued]>
[2022-11-30T19:03:52.649+0000] {taskinstance.py:1165} INFO - Dependencies all met for <TaskInstance: first_dag.ford_dataset manual__2022-11-30T19:03:48.187324+00:00 [queued]>
[2022-11-30T19:03:52.650+0000] {taskinstance.py:1362} INFO - 
--------------------------------------------------------------------------------
[2022-11-30T19:03:52.650+0000] {taskinstance.py:1363} INFO - Starting attempt 1 of 1
[2022-11-30T19:03:52.651+0000] {taskinstance.py:1364} INFO - 
--------------------------------------------------------------------------------
[2022-11-30T19:03:52.665+0000] {taskinstance.py:1383} INFO - Executing <Task(PythonOperator): ford_dataset> on 2022-11-30 19:03:48.187324+00:00
[2022-11-30T19:03:52.689+0000] {standard_task_runner.py:55} INFO - Started process 7620 to run task
[2022-11-30T19:03:52.692+0000] {standard_task_runner.py:82} INFO - Running: ['***', 'tasks', 'run', 'first_dag', 'ford_dataset', 'manual__2022-11-30T19:03:48.187324+00:00', '--job-id', '726', '--raw', '--subdir', 'DAGS_FOLDER/***1t.py', '--cfg-path', '/tmp/tmpjf0w7w94']
[2022-11-30T19:03:52.694+0000] {standard_task_runner.py:83} INFO - Job 726: Subtask ford_dataset
[2022-11-30T19:03:52.757+0000] {task_command.py:376} INFO - Running <TaskInstance: first_dag.ford_dataset manual__2022-11-30T19:03:48.187324+00:00 [running]> on host debdf09646d4
[2022-11-30T19:03:52.824+0000] {taskinstance.py:1592} INFO - Exporting the following env vars:
AIRFLOW_CTX_DAG_OWNER=***
AIRFLOW_CTX_DAG_ID=first_dag
AIRFLOW_CTX_TASK_ID=ford_dataset
AIRFLOW_CTX_EXECUTION_DATE=2022-11-30T19:03:48.187324+00:00
AIRFLOW_CTX_TRY_NUMBER=1
AIRFLOW_CTX_DAG_RUN_ID=manual__2022-11-30T19:03:48.187324+00:00
[2022-11-30T19:03:56.282+0000] {taskinstance.py:1851} ERROR - Task failed with exception
Traceback (most recent call last):
  File "/home/airflow/.local/lib/python3.7/site-packages/airflow/operators/python.py", line 175, in execute
    return_value = self.execute_callable()
  File "/home/airflow/.local/lib/python3.7/site-packages/airflow/operators/python.py", line 193, in execute_callable
    return self.python_callable(*self.op_args, **self.op_kwargs)
  File "/opt/airflow/dags/airflow1t.py", line 25, in download_df
    value = Variable.get("foo")
  File "/home/airflow/.local/lib/python3.7/site-packages/airflow/models/variable.py", line 141, in get
    raise KeyError(f'Variable {key} does not exist')
KeyError: 'Variable foo does not exist'
[2022-11-30T19:03:56.292+0000] {taskinstance.py:1406} INFO - Marking task as FAILED. dag_id=first_dag, task_id=ford_dataset, execution_date=20221130T190348, start_date=20221130T190352, end_date=20221130T190356
[2022-11-30T19:03:56.306+0000] {standard_task_runner.py:105} ERROR - Failed to execute job 726 for task ford_dataset ('Variable foo does not exist'; 7620)
[2022-11-30T19:03:56.320+0000] {local_task_job.py:159} INFO - Task exited with return code 1
[2022-11-30T19:03:56.337+0000] {taskinstance.py:2623} INFO - 0 downstream tasks scheduled from follow-on schedule check
