[2022-12-05T16:45:59.078+0000] {taskinstance.py:1165} INFO - Dependencies all met for <TaskInstance: first_dag.number_task manual__2022-12-05T16:45:49.876562+00:00 [queued]>
[2022-12-05T16:45:59.088+0000] {taskinstance.py:1165} INFO - Dependencies all met for <TaskInstance: first_dag.number_task manual__2022-12-05T16:45:49.876562+00:00 [queued]>
[2022-12-05T16:45:59.088+0000] {taskinstance.py:1362} INFO - 
--------------------------------------------------------------------------------
[2022-12-05T16:45:59.089+0000] {taskinstance.py:1363} INFO - Starting attempt 1 of 1
[2022-12-05T16:45:59.089+0000] {taskinstance.py:1364} INFO - 
--------------------------------------------------------------------------------
[2022-12-05T16:45:59.104+0000] {taskinstance.py:1383} INFO - Executing <Task(PythonOperator): number_task> on 2022-12-05 16:45:49.876562+00:00
[2022-12-05T16:45:59.109+0000] {standard_task_runner.py:55} INFO - Started process 2784 to run task
[2022-12-05T16:45:59.112+0000] {standard_task_runner.py:82} INFO - Running: ['***', 'tasks', 'run', 'first_dag', 'number_task', 'manual__2022-12-05T16:45:49.876562+00:00', '--job-id', '1024', '--raw', '--subdir', 'DAGS_FOLDER/***1t.py', '--cfg-path', '/tmp/tmpqv2dtug8']
[2022-12-05T16:45:59.114+0000] {standard_task_runner.py:83} INFO - Job 1024: Subtask number_task
[2022-12-05T16:45:59.174+0000] {task_command.py:376} INFO - Running <TaskInstance: first_dag.number_task manual__2022-12-05T16:45:49.876562+00:00 [running]> on host debdf09646d4
[2022-12-05T16:45:59.270+0000] {taskinstance.py:1592} INFO - Exporting the following env vars:
AIRFLOW_CTX_DAG_OWNER=***
AIRFLOW_CTX_DAG_ID=first_dag
AIRFLOW_CTX_TASK_ID=number_task
AIRFLOW_CTX_EXECUTION_DATE=2022-12-05T16:45:49.876562+00:00
AIRFLOW_CTX_TRY_NUMBER=1
AIRFLOW_CTX_DAG_RUN_ID=manual__2022-12-05T16:45:49.876562+00:00
[2022-12-05T16:45:59.272+0000] {taskinstance.py:1851} ERROR - Task failed with exception
Traceback (most recent call last):
  File "/home/airflow/.local/lib/python3.7/site-packages/airflow/operators/python.py", line 175, in execute
    return_value = self.execute_callable()
  File "/home/airflow/.local/lib/python3.7/site-packages/airflow/operators/python.py", line 193, in execute_callable
    return self.python_callable(*self.op_args, **self.op_kwargs)
  File "/opt/airflow/dags/airflow1t.py", line 38, in random_number
    with open("C:/Users/admin/PycharmProjects/pythonProject1/file.txt", "w") as file:
FileNotFoundError: [Errno 2] No such file or directory: 'C:/Users/admin/PycharmProjects/pythonProject1/file.txt'
[2022-12-05T16:45:59.282+0000] {taskinstance.py:1406} INFO - Marking task as FAILED. dag_id=first_dag, task_id=number_task, execution_date=20221205T164549, start_date=20221205T164559, end_date=20221205T164559
[2022-12-05T16:45:59.296+0000] {standard_task_runner.py:105} ERROR - Failed to execute job 1024 for task number_task ([Errno 2] No such file or directory: 'C:/Users/admin/PycharmProjects/pythonProject1/file.txt'; 2784)
[2022-12-05T16:45:59.330+0000] {local_task_job.py:159} INFO - Task exited with return code 1
[2022-12-05T16:45:59.349+0000] {taskinstance.py:2623} INFO - 0 downstream tasks scheduled from follow-on schedule check
