[2022-12-05T19:04:26.494+0000] {taskinstance.py:1165} INFO - Dependencies all met for <TaskInstance: first_dag.sum_task manual__2022-12-05T19:04:25.401461+00:00 [queued]>
[2022-12-05T19:04:26.509+0000] {taskinstance.py:1165} INFO - Dependencies all met for <TaskInstance: first_dag.sum_task manual__2022-12-05T19:04:25.401461+00:00 [queued]>
[2022-12-05T19:04:26.509+0000] {taskinstance.py:1362} INFO - 
--------------------------------------------------------------------------------
[2022-12-05T19:04:26.510+0000] {taskinstance.py:1363} INFO - Starting attempt 1 of 1
[2022-12-05T19:04:26.510+0000] {taskinstance.py:1364} INFO - 
--------------------------------------------------------------------------------
[2022-12-05T19:04:26.526+0000] {taskinstance.py:1383} INFO - Executing <Task(PythonOperator): sum_task> on 2022-12-05 19:04:25.401461+00:00
[2022-12-05T19:04:26.532+0000] {standard_task_runner.py:55} INFO - Started process 10101 to run task
[2022-12-05T19:04:26.536+0000] {standard_task_runner.py:82} INFO - Running: ['***', 'tasks', 'run', 'first_dag', 'sum_task', 'manual__2022-12-05T19:04:25.401461+00:00', '--job-id', '1274', '--raw', '--subdir', 'DAGS_FOLDER/***1t.py', '--cfg-path', '/tmp/tmp6b97qpeg']
[2022-12-05T19:04:26.538+0000] {standard_task_runner.py:83} INFO - Job 1274: Subtask sum_task
[2022-12-05T19:04:26.601+0000] {task_command.py:376} INFO - Running <TaskInstance: first_dag.sum_task manual__2022-12-05T19:04:25.401461+00:00 [running]> on host debdf09646d4
[2022-12-05T19:04:26.673+0000] {taskinstance.py:1592} INFO - Exporting the following env vars:
AIRFLOW_CTX_DAG_OWNER=***
AIRFLOW_CTX_DAG_ID=first_dag
AIRFLOW_CTX_TASK_ID=sum_task
AIRFLOW_CTX_EXECUTION_DATE=2022-12-05T19:04:25.401461+00:00
AIRFLOW_CTX_TRY_NUMBER=1
AIRFLOW_CTX_DAG_RUN_ID=manual__2022-12-05T19:04:25.401461+00:00
[2022-12-05T19:04:26.675+0000] {taskinstance.py:1851} ERROR - Task failed with exception
Traceback (most recent call last):
  File "/home/airflow/.local/lib/python3.7/site-packages/airflow/operators/python.py", line 175, in execute
    return_value = self.execute_callable()
  File "/home/airflow/.local/lib/python3.7/site-packages/airflow/operators/python.py", line 193, in execute_callable
    return self.python_callable(*self.op_args, **self.op_kwargs)
  File "/opt/airflow/dags/airflow1t.py", line 53, in summa
    f.write(str(raz))
io.UnsupportedOperation: not writable
[2022-12-05T19:04:26.686+0000] {taskinstance.py:1406} INFO - Marking task as FAILED. dag_id=first_dag, task_id=sum_task, execution_date=20221205T190425, start_date=20221205T190426, end_date=20221205T190426
[2022-12-05T19:04:26.699+0000] {standard_task_runner.py:105} ERROR - Failed to execute job 1274 for task sum_task (not writable; 10101)
[2022-12-05T19:04:26.707+0000] {local_task_job.py:159} INFO - Task exited with return code 1
[2022-12-05T19:04:26.724+0000] {taskinstance.py:2623} INFO - 0 downstream tasks scheduled from follow-on schedule check
