[2022-12-01T17:34:52.221+0000] {taskinstance.py:1165} INFO - Dependencies all met for <TaskInstance: first_dag.pull_task manual__2022-12-01T17:34:47.239647+00:00 [queued]>
[2022-12-01T17:34:52.236+0000] {taskinstance.py:1165} INFO - Dependencies all met for <TaskInstance: first_dag.pull_task manual__2022-12-01T17:34:47.239647+00:00 [queued]>
[2022-12-01T17:34:52.236+0000] {taskinstance.py:1362} INFO - 
--------------------------------------------------------------------------------
[2022-12-01T17:34:52.237+0000] {taskinstance.py:1363} INFO - Starting attempt 1 of 1
[2022-12-01T17:34:52.238+0000] {taskinstance.py:1364} INFO - 
--------------------------------------------------------------------------------
[2022-12-01T17:34:52.255+0000] {taskinstance.py:1383} INFO - Executing <Task(PythonOperator): pull_task> on 2022-12-01 17:34:47.239647+00:00
[2022-12-01T17:34:52.260+0000] {standard_task_runner.py:55} INFO - Started process 4199 to run task
[2022-12-01T17:34:52.264+0000] {standard_task_runner.py:82} INFO - Running: ['***', 'tasks', 'run', 'first_dag', 'pull_task', 'manual__2022-12-01T17:34:47.239647+00:00', '--job-id', '886', '--raw', '--subdir', 'DAGS_FOLDER/***1t.py', '--cfg-path', '/tmp/tmpcghzmd2d']
[2022-12-01T17:34:52.266+0000] {standard_task_runner.py:83} INFO - Job 886: Subtask pull_task
[2022-12-01T17:34:52.349+0000] {task_command.py:376} INFO - Running <TaskInstance: first_dag.pull_task manual__2022-12-01T17:34:47.239647+00:00 [running]> on host debdf09646d4
[2022-12-01T17:34:52.425+0000] {taskinstance.py:1592} INFO - Exporting the following env vars:
AIRFLOW_CTX_DAG_OWNER=***
AIRFLOW_CTX_DAG_ID=first_dag
AIRFLOW_CTX_TASK_ID=pull_task
AIRFLOW_CTX_EXECUTION_DATE=2022-12-01T17:34:47.239647+00:00
AIRFLOW_CTX_TRY_NUMBER=1
AIRFLOW_CTX_DAG_RUN_ID=manual__2022-12-01T17:34:47.239647+00:00
[2022-12-01T17:34:52.428+0000] {taskinstance.py:1851} ERROR - Task failed with exception
Traceback (most recent call last):
  File "/home/airflow/.local/lib/python3.7/site-packages/airflow/operators/python.py", line 175, in execute
    return_value = self.execute_callable()
  File "/home/airflow/.local/lib/python3.7/site-packages/airflow/operators/python.py", line 193, in execute_callable
    return self.python_callable(*self.op_args, **self.op_kwargs)
  File "/opt/airflow/dags/airflow1t.py", line 30, in pull_function
    df = pd.read_csv("value")
  File "/home/airflow/.local/lib/python3.7/site-packages/pandas/util/_decorators.py", line 311, in wrapper
    return func(*args, **kwargs)
  File "/home/airflow/.local/lib/python3.7/site-packages/pandas/io/parsers/readers.py", line 586, in read_csv
    return _read(filepath_or_buffer, kwds)
  File "/home/airflow/.local/lib/python3.7/site-packages/pandas/io/parsers/readers.py", line 482, in _read
    parser = TextFileReader(filepath_or_buffer, **kwds)
  File "/home/airflow/.local/lib/python3.7/site-packages/pandas/io/parsers/readers.py", line 811, in __init__
    self._engine = self._make_engine(self.engine)
  File "/home/airflow/.local/lib/python3.7/site-packages/pandas/io/parsers/readers.py", line 1040, in _make_engine
    return mapping[engine](self.f, **self.options)  # type: ignore[call-arg]
  File "/home/airflow/.local/lib/python3.7/site-packages/pandas/io/parsers/c_parser_wrapper.py", line 51, in __init__
    self._open_handles(src, kwds)
  File "/home/airflow/.local/lib/python3.7/site-packages/pandas/io/parsers/base_parser.py", line 229, in _open_handles
    errors=kwds.get("encoding_errors", "strict"),
  File "/home/airflow/.local/lib/python3.7/site-packages/pandas/io/common.py", line 707, in get_handle
    newline="",
FileNotFoundError: [Errno 2] No such file or directory: 'value'
[2022-12-01T17:34:52.440+0000] {taskinstance.py:1406} INFO - Marking task as FAILED. dag_id=first_dag, task_id=pull_task, execution_date=20221201T173447, start_date=20221201T173452, end_date=20221201T173452
[2022-12-01T17:34:52.453+0000] {standard_task_runner.py:105} ERROR - Failed to execute job 886 for task pull_task ([Errno 2] No such file or directory: 'value'; 4199)
[2022-12-01T17:34:52.475+0000] {local_task_job.py:159} INFO - Task exited with return code 1
[2022-12-01T17:34:52.507+0000] {taskinstance.py:2623} INFO - 0 downstream tasks scheduled from follow-on schedule check
