[2022-12-05T17:15:29.370+0000] {taskinstance.py:1165} INFO - Dependencies all met for <TaskInstance: first_dag.number_task manual__2022-12-05T17:15:21.256493+00:00 [queued]>
[2022-12-05T17:15:29.381+0000] {taskinstance.py:1165} INFO - Dependencies all met for <TaskInstance: first_dag.number_task manual__2022-12-05T17:15:21.256493+00:00 [queued]>
[2022-12-05T17:15:29.381+0000] {taskinstance.py:1362} INFO - 
--------------------------------------------------------------------------------
[2022-12-05T17:15:29.382+0000] {taskinstance.py:1363} INFO - Starting attempt 1 of 1
[2022-12-05T17:15:29.382+0000] {taskinstance.py:1364} INFO - 
--------------------------------------------------------------------------------
[2022-12-05T17:15:29.397+0000] {taskinstance.py:1383} INFO - Executing <Task(PythonOperator): number_task> on 2022-12-05 17:15:21.256493+00:00
[2022-12-05T17:15:29.402+0000] {standard_task_runner.py:55} INFO - Started process 4327 to run task
[2022-12-05T17:15:29.405+0000] {standard_task_runner.py:82} INFO - Running: ['***', 'tasks', 'run', 'first_dag', 'number_task', 'manual__2022-12-05T17:15:21.256493+00:00', '--job-id', '1072', '--raw', '--subdir', 'DAGS_FOLDER/***1t.py', '--cfg-path', '/tmp/tmp94zxz2s0']
[2022-12-05T17:15:29.407+0000] {standard_task_runner.py:83} INFO - Job 1072: Subtask number_task
[2022-12-05T17:15:29.468+0000] {task_command.py:376} INFO - Running <TaskInstance: first_dag.number_task manual__2022-12-05T17:15:21.256493+00:00 [running]> on host debdf09646d4
[2022-12-05T17:15:29.534+0000] {taskinstance.py:1592} INFO - Exporting the following env vars:
AIRFLOW_CTX_DAG_OWNER=***
AIRFLOW_CTX_DAG_ID=first_dag
AIRFLOW_CTX_TASK_ID=number_task
AIRFLOW_CTX_EXECUTION_DATE=2022-12-05T17:15:21.256493+00:00
AIRFLOW_CTX_TRY_NUMBER=1
AIRFLOW_CTX_DAG_RUN_ID=manual__2022-12-05T17:15:21.256493+00:00
[2022-12-05T17:15:29.535+0000] {logging_mixin.py:137} INFO - 82   24
[2022-12-05T17:15:29.536+0000] {taskinstance.py:1851} ERROR - Task failed with exception
Traceback (most recent call last):
  File "/home/airflow/.local/lib/python3.7/site-packages/airflow/operators/python.py", line 175, in execute
    return_value = self.execute_callable()
  File "/home/airflow/.local/lib/python3.7/site-packages/airflow/operators/python.py", line 193, in execute_callable
    return self.python_callable(*self.op_args, **self.op_kwargs)
  File "/opt/airflow/dags/airflow1t.py", line 40, in random_number
    file.write(str(number1),' ',str(number2))
TypeError: write() takes exactly one argument (3 given)
[2022-12-05T17:15:29.545+0000] {taskinstance.py:1406} INFO - Marking task as FAILED. dag_id=first_dag, task_id=number_task, execution_date=20221205T171521, start_date=20221205T171529, end_date=20221205T171529
[2022-12-05T17:15:29.558+0000] {standard_task_runner.py:105} ERROR - Failed to execute job 1072 for task number_task (write() takes exactly one argument (3 given); 4327)
[2022-12-05T17:15:29.577+0000] {local_task_job.py:159} INFO - Task exited with return code 1
[2022-12-05T17:15:29.593+0000] {taskinstance.py:2623} INFO - 0 downstream tasks scheduled from follow-on schedule check
