[2022-12-05T18:22:36.430+0000] {taskinstance.py:1165} INFO - Dependencies all met for <TaskInstance: first_dag.sum_task manual__2022-12-05T18:22:26.379699+00:00 [queued]>
[2022-12-05T18:22:36.440+0000] {taskinstance.py:1165} INFO - Dependencies all met for <TaskInstance: first_dag.sum_task manual__2022-12-05T18:22:26.379699+00:00 [queued]>
[2022-12-05T18:22:36.441+0000] {taskinstance.py:1362} INFO - 
--------------------------------------------------------------------------------
[2022-12-05T18:22:36.441+0000] {taskinstance.py:1363} INFO - Starting attempt 1 of 1
[2022-12-05T18:22:36.442+0000] {taskinstance.py:1364} INFO - 
--------------------------------------------------------------------------------
[2022-12-05T18:22:36.457+0000] {taskinstance.py:1383} INFO - Executing <Task(PythonOperator): sum_task> on 2022-12-05 18:22:26.379699+00:00
[2022-12-05T18:22:36.462+0000] {standard_task_runner.py:55} INFO - Started process 7752 to run task
[2022-12-05T18:22:36.465+0000] {standard_task_runner.py:82} INFO - Running: ['***', 'tasks', 'run', 'first_dag', 'sum_task', 'manual__2022-12-05T18:22:26.379699+00:00', '--job-id', '1154', '--raw', '--subdir', 'DAGS_FOLDER/***1t.py', '--cfg-path', '/tmp/tmp_0sdhegt']
[2022-12-05T18:22:36.467+0000] {standard_task_runner.py:83} INFO - Job 1154: Subtask sum_task
[2022-12-05T18:22:36.526+0000] {task_command.py:376} INFO - Running <TaskInstance: first_dag.sum_task manual__2022-12-05T18:22:26.379699+00:00 [running]> on host debdf09646d4
[2022-12-05T18:22:36.595+0000] {taskinstance.py:1592} INFO - Exporting the following env vars:
AIRFLOW_CTX_DAG_OWNER=***
AIRFLOW_CTX_DAG_ID=first_dag
AIRFLOW_CTX_TASK_ID=sum_task
AIRFLOW_CTX_EXECUTION_DATE=2022-12-05T18:22:26.379699+00:00
AIRFLOW_CTX_TRY_NUMBER=1
AIRFLOW_CTX_DAG_RUN_ID=manual__2022-12-05T18:22:26.379699+00:00
[2022-12-05T18:22:36.596+0000] {taskinstance.py:1851} ERROR - Task failed with exception
Traceback (most recent call last):
  File "/home/airflow/.local/lib/python3.7/site-packages/airflow/operators/python.py", line 175, in execute
    return_value = self.execute_callable()
  File "/home/airflow/.local/lib/python3.7/site-packages/airflow/operators/python.py", line 193, in execute_callable
    return self.python_callable(*self.op_args, **self.op_kwargs)
  File "/opt/airflow/dags/airflow1t.py", line 48, in summa
    result2 = [[int(n)] for n in f.read().split()[1]]
IndexError: list index out of range
[2022-12-05T18:22:36.606+0000] {taskinstance.py:1406} INFO - Marking task as FAILED. dag_id=first_dag, task_id=sum_task, execution_date=20221205T182226, start_date=20221205T182236, end_date=20221205T182236
[2022-12-05T18:22:36.617+0000] {standard_task_runner.py:105} ERROR - Failed to execute job 1154 for task sum_task (list index out of range; 7752)
[2022-12-05T18:22:36.637+0000] {local_task_job.py:159} INFO - Task exited with return code 1
[2022-12-05T18:22:36.653+0000] {taskinstance.py:2623} INFO - 0 downstream tasks scheduled from follow-on schedule check
