[2022-12-05T16:35:08.297+0000] {taskinstance.py:1165} INFO - Dependencies all met for <TaskInstance: first_dag.number_task manual__2022-12-05T16:34:55.012178+00:00 [queued]>
[2022-12-05T16:35:08.313+0000] {taskinstance.py:1165} INFO - Dependencies all met for <TaskInstance: first_dag.number_task manual__2022-12-05T16:34:55.012178+00:00 [queued]>
[2022-12-05T16:35:08.314+0000] {taskinstance.py:1362} INFO - 
--------------------------------------------------------------------------------
[2022-12-05T16:35:08.314+0000] {taskinstance.py:1363} INFO - Starting attempt 1 of 1
[2022-12-05T16:35:08.315+0000] {taskinstance.py:1364} INFO - 
--------------------------------------------------------------------------------
[2022-12-05T16:35:08.332+0000] {taskinstance.py:1383} INFO - Executing <Task(PythonOperator): number_task> on 2022-12-05 16:34:55.012178+00:00
[2022-12-05T16:35:08.337+0000] {standard_task_runner.py:55} INFO - Started process 2161 to run task
[2022-12-05T16:35:08.341+0000] {standard_task_runner.py:82} INFO - Running: ['***', 'tasks', 'run', 'first_dag', 'number_task', 'manual__2022-12-05T16:34:55.012178+00:00', '--job-id', '988', '--raw', '--subdir', 'DAGS_FOLDER/***1t.py', '--cfg-path', '/tmp/tmp1hk6vx32']
[2022-12-05T16:35:08.342+0000] {standard_task_runner.py:83} INFO - Job 988: Subtask number_task
[2022-12-05T16:35:08.448+0000] {task_command.py:376} INFO - Running <TaskInstance: first_dag.number_task manual__2022-12-05T16:34:55.012178+00:00 [running]> on host debdf09646d4
[2022-12-05T16:35:08.557+0000] {taskinstance.py:1592} INFO - Exporting the following env vars:
AIRFLOW_CTX_DAG_OWNER=***
AIRFLOW_CTX_DAG_ID=first_dag
AIRFLOW_CTX_TASK_ID=number_task
AIRFLOW_CTX_EXECUTION_DATE=2022-12-05T16:34:55.012178+00:00
AIRFLOW_CTX_TRY_NUMBER=1
AIRFLOW_CTX_DAG_RUN_ID=manual__2022-12-05T16:34:55.012178+00:00
[2022-12-05T16:35:08.564+0000] {logging_mixin.py:137} INFO - 99   78
[2022-12-05T16:35:08.565+0000] {taskinstance.py:1851} ERROR - Task failed with exception
Traceback (most recent call last):
  File "/home/airflow/.local/lib/python3.7/site-packages/airflow/operators/python.py", line 175, in execute
    return_value = self.execute_callable()
  File "/home/airflow/.local/lib/python3.7/site-packages/airflow/operators/python.py", line 193, in execute_callable
    return self.python_callable(*self.op_args, **self.op_kwargs)
  File "/opt/airflow/dags/airflow1t.py", line 38, in random_number
    file_1 = open("C:/Users/admin/PycharmProjects/pythonProject1/file.txt", "r")
FileNotFoundError: [Errno 2] No such file or directory: 'C:/Users/admin/PycharmProjects/pythonProject1/file.txt'
[2022-12-05T16:35:08.578+0000] {taskinstance.py:1406} INFO - Marking task as FAILED. dag_id=first_dag, task_id=number_task, execution_date=20221205T163455, start_date=20221205T163508, end_date=20221205T163508
[2022-12-05T16:35:08.614+0000] {standard_task_runner.py:105} ERROR - Failed to execute job 988 for task number_task ([Errno 2] No such file or directory: 'C:/Users/admin/PycharmProjects/pythonProject1/file.txt'; 2161)
[2022-12-05T16:35:08.632+0000] {local_task_job.py:159} INFO - Task exited with return code 1
[2022-12-05T16:35:08.663+0000] {taskinstance.py:2623} INFO - 0 downstream tasks scheduled from follow-on schedule check
