[2022-12-05T17:02:53.807+0000] {taskinstance.py:1165} INFO - Dependencies all met for <TaskInstance: first_dag.number_task manual__2022-12-05T17:02:42.540465+00:00 [queued]>
[2022-12-05T17:02:53.817+0000] {taskinstance.py:1165} INFO - Dependencies all met for <TaskInstance: first_dag.number_task manual__2022-12-05T17:02:42.540465+00:00 [queued]>
[2022-12-05T17:02:53.817+0000] {taskinstance.py:1362} INFO - 
--------------------------------------------------------------------------------
[2022-12-05T17:02:53.818+0000] {taskinstance.py:1363} INFO - Starting attempt 1 of 1
[2022-12-05T17:02:53.818+0000] {taskinstance.py:1364} INFO - 
--------------------------------------------------------------------------------
[2022-12-05T17:02:53.833+0000] {taskinstance.py:1383} INFO - Executing <Task(PythonOperator): number_task> on 2022-12-05 17:02:42.540465+00:00
[2022-12-05T17:02:53.838+0000] {standard_task_runner.py:55} INFO - Started process 3655 to run task
[2022-12-05T17:02:53.842+0000] {standard_task_runner.py:82} INFO - Running: ['***', 'tasks', 'run', 'first_dag', 'number_task', 'manual__2022-12-05T17:02:42.540465+00:00', '--job-id', '1048', '--raw', '--subdir', 'DAGS_FOLDER/***1t.py', '--cfg-path', '/tmp/tmp_coyozy5']
[2022-12-05T17:02:53.844+0000] {standard_task_runner.py:83} INFO - Job 1048: Subtask number_task
[2022-12-05T17:02:53.908+0000] {task_command.py:376} INFO - Running <TaskInstance: first_dag.number_task manual__2022-12-05T17:02:42.540465+00:00 [running]> on host debdf09646d4
[2022-12-05T17:02:53.974+0000] {taskinstance.py:1592} INFO - Exporting the following env vars:
AIRFLOW_CTX_DAG_OWNER=***
AIRFLOW_CTX_DAG_ID=first_dag
AIRFLOW_CTX_TASK_ID=number_task
AIRFLOW_CTX_EXECUTION_DATE=2022-12-05T17:02:42.540465+00:00
AIRFLOW_CTX_TRY_NUMBER=1
AIRFLOW_CTX_DAG_RUN_ID=manual__2022-12-05T17:02:42.540465+00:00
[2022-12-05T17:02:53.975+0000] {logging_mixin.py:137} INFO - 98   83
[2022-12-05T17:02:53.976+0000] {taskinstance.py:1851} ERROR - Task failed with exception
Traceback (most recent call last):
  File "/home/airflow/.local/lib/python3.7/site-packages/airflow/operators/python.py", line 175, in execute
    return_value = self.execute_callable()
  File "/home/airflow/.local/lib/python3.7/site-packages/airflow/operators/python.py", line 193, in execute_callable
    return self.python_callable(*self.op_args, **self.op_kwargs)
  File "/opt/airflow/dags/airflow1t.py", line 41, in random_number
    path.read_text()
  File "/usr/local/lib/python3.7/pathlib.py", line 1221, in read_text
    with self.open(mode='r', encoding=encoding, errors=errors) as f:
  File "/usr/local/lib/python3.7/pathlib.py", line 1208, in open
    opener=self._opener)
  File "/usr/local/lib/python3.7/pathlib.py", line 1063, in _opener
    return self._accessor.open(self, flags, mode)
FileNotFoundError: [Errno 2] No such file or directory: '/opt/airflow/file.txt'
[2022-12-05T17:02:53.986+0000] {taskinstance.py:1406} INFO - Marking task as FAILED. dag_id=first_dag, task_id=number_task, execution_date=20221205T170242, start_date=20221205T170253, end_date=20221205T170253
[2022-12-05T17:02:53.999+0000] {standard_task_runner.py:105} ERROR - Failed to execute job 1048 for task number_task ([Errno 2] No such file or directory: '/opt/airflow/file.txt'; 3655)
[2022-12-05T17:02:54.013+0000] {local_task_job.py:159} INFO - Task exited with return code 1
[2022-12-05T17:02:54.030+0000] {taskinstance.py:2623} INFO - 0 downstream tasks scheduled from follow-on schedule check
