[2022-12-05T16:33:32.718+0000] {taskinstance.py:1165} INFO - Dependencies all met for <TaskInstance: first_dag.number_task manual__2022-12-05T16:33:16.620753+00:00 [queued]>
[2022-12-05T16:33:32.727+0000] {taskinstance.py:1165} INFO - Dependencies all met for <TaskInstance: first_dag.number_task manual__2022-12-05T16:33:16.620753+00:00 [queued]>
[2022-12-05T16:33:32.728+0000] {taskinstance.py:1362} INFO - 
--------------------------------------------------------------------------------
[2022-12-05T16:33:32.728+0000] {taskinstance.py:1363} INFO - Starting attempt 1 of 1
[2022-12-05T16:33:32.729+0000] {taskinstance.py:1364} INFO - 
--------------------------------------------------------------------------------
[2022-12-05T16:33:32.746+0000] {taskinstance.py:1383} INFO - Executing <Task(PythonOperator): number_task> on 2022-12-05 16:33:16.620753+00:00
[2022-12-05T16:33:32.750+0000] {standard_task_runner.py:55} INFO - Started process 2061 to run task
[2022-12-05T16:33:32.753+0000] {standard_task_runner.py:82} INFO - Running: ['***', 'tasks', 'run', 'first_dag', 'number_task', 'manual__2022-12-05T16:33:16.620753+00:00', '--job-id', '982', '--raw', '--subdir', 'DAGS_FOLDER/***1t.py', '--cfg-path', '/tmp/tmprwvu363a']
[2022-12-05T16:33:32.755+0000] {standard_task_runner.py:83} INFO - Job 982: Subtask number_task
[2022-12-05T16:33:32.816+0000] {task_command.py:376} INFO - Running <TaskInstance: first_dag.number_task manual__2022-12-05T16:33:16.620753+00:00 [running]> on host debdf09646d4
[2022-12-05T16:33:32.883+0000] {taskinstance.py:1592} INFO - Exporting the following env vars:
AIRFLOW_CTX_DAG_OWNER=***
AIRFLOW_CTX_DAG_ID=first_dag
AIRFLOW_CTX_TASK_ID=number_task
AIRFLOW_CTX_EXECUTION_DATE=2022-12-05T16:33:16.620753+00:00
AIRFLOW_CTX_TRY_NUMBER=1
AIRFLOW_CTX_DAG_RUN_ID=manual__2022-12-05T16:33:16.620753+00:00
[2022-12-05T16:33:32.884+0000] {logging_mixin.py:137} INFO - 3   38
[2022-12-05T16:33:32.884+0000] {taskinstance.py:1851} ERROR - Task failed with exception
Traceback (most recent call last):
  File "/home/airflow/.local/lib/python3.7/site-packages/airflow/operators/python.py", line 175, in execute
    return_value = self.execute_callable()
  File "/home/airflow/.local/lib/python3.7/site-packages/airflow/operators/python.py", line 193, in execute_callable
    return self.python_callable(*self.op_args, **self.op_kwargs)
  File "/opt/airflow/dags/airflow1t.py", line 38, in random_number
    file_1 = open("C:/Users/admin/PycharmProjects/pythonProject1/file.txt", "w")
FileNotFoundError: [Errno 2] No such file or directory: 'C:/Users/admin/PycharmProjects/pythonProject1/file.txt'
[2022-12-05T16:33:32.894+0000] {taskinstance.py:1406} INFO - Marking task as FAILED. dag_id=first_dag, task_id=number_task, execution_date=20221205T163316, start_date=20221205T163332, end_date=20221205T163332
[2022-12-05T16:33:32.905+0000] {standard_task_runner.py:105} ERROR - Failed to execute job 982 for task number_task ([Errno 2] No such file or directory: 'C:/Users/admin/PycharmProjects/pythonProject1/file.txt'; 2061)
[2022-12-05T16:33:32.925+0000] {local_task_job.py:159} INFO - Task exited with return code 1
[2022-12-05T16:33:32.939+0000] {taskinstance.py:2623} INFO - 0 downstream tasks scheduled from follow-on schedule check
