[2022-12-05T16:58:21.361+0000] {taskinstance.py:1165} INFO - Dependencies all met for <TaskInstance: first_dag.number_task manual__2022-12-05T16:58:10.772413+00:00 [queued]>
[2022-12-05T16:58:21.375+0000] {taskinstance.py:1165} INFO - Dependencies all met for <TaskInstance: first_dag.number_task manual__2022-12-05T16:58:10.772413+00:00 [queued]>
[2022-12-05T16:58:21.376+0000] {taskinstance.py:1362} INFO - 
--------------------------------------------------------------------------------
[2022-12-05T16:58:21.376+0000] {taskinstance.py:1363} INFO - Starting attempt 1 of 1
[2022-12-05T16:58:21.376+0000] {taskinstance.py:1364} INFO - 
--------------------------------------------------------------------------------
[2022-12-05T16:58:21.391+0000] {taskinstance.py:1383} INFO - Executing <Task(PythonOperator): number_task> on 2022-12-05 16:58:10.772413+00:00
[2022-12-05T16:58:21.396+0000] {standard_task_runner.py:55} INFO - Started process 3426 to run task
[2022-12-05T16:58:21.400+0000] {standard_task_runner.py:82} INFO - Running: ['***', 'tasks', 'run', 'first_dag', 'number_task', 'manual__2022-12-05T16:58:10.772413+00:00', '--job-id', '1042', '--raw', '--subdir', 'DAGS_FOLDER/***1t.py', '--cfg-path', '/tmp/tmpc72rzys7']
[2022-12-05T16:58:21.402+0000] {standard_task_runner.py:83} INFO - Job 1042: Subtask number_task
[2022-12-05T16:58:21.466+0000] {task_command.py:376} INFO - Running <TaskInstance: first_dag.number_task manual__2022-12-05T16:58:10.772413+00:00 [running]> on host debdf09646d4
[2022-12-05T16:58:21.541+0000] {taskinstance.py:1592} INFO - Exporting the following env vars:
AIRFLOW_CTX_DAG_OWNER=***
AIRFLOW_CTX_DAG_ID=first_dag
AIRFLOW_CTX_TASK_ID=number_task
AIRFLOW_CTX_EXECUTION_DATE=2022-12-05T16:58:10.772413+00:00
AIRFLOW_CTX_TRY_NUMBER=1
AIRFLOW_CTX_DAG_RUN_ID=manual__2022-12-05T16:58:10.772413+00:00
[2022-12-05T16:58:21.542+0000] {logging_mixin.py:137} INFO - 39   9
[2022-12-05T16:58:21.542+0000] {logging_mixin.py:137} INFO - /opt/***/file.txt 
[2022-12-05T16:58:21.543+0000] {taskinstance.py:1851} ERROR - Task failed with exception
Traceback (most recent call last):
  File "/home/airflow/.local/lib/python3.7/site-packages/airflow/operators/python.py", line 175, in execute
    return_value = self.execute_callable()
  File "/home/airflow/.local/lib/python3.7/site-packages/airflow/operators/python.py", line 193, in execute_callable
    return self.python_callable(*self.op_args, **self.op_kwargs)
  File "/opt/airflow/dags/airflow1t.py", line 41, in random_number
    p=open('file.txt')
FileNotFoundError: [Errno 2] No such file or directory: 'file.txt'
[2022-12-05T16:58:21.553+0000] {taskinstance.py:1406} INFO - Marking task as FAILED. dag_id=first_dag, task_id=number_task, execution_date=20221205T165810, start_date=20221205T165821, end_date=20221205T165821
[2022-12-05T16:58:21.566+0000] {standard_task_runner.py:105} ERROR - Failed to execute job 1042 for task number_task ([Errno 2] No such file or directory: 'file.txt'; 3426)
[2022-12-05T16:58:21.612+0000] {local_task_job.py:159} INFO - Task exited with return code 1
[2022-12-05T16:58:21.630+0000] {taskinstance.py:2623} INFO - 0 downstream tasks scheduled from follow-on schedule check
